{
    DataVersion: 3955,
    size: [11, 5, 7],
    data: [
        {pos: [0, 0, 0], state: "minecraft:grass_block{snowy:false}"},
        {pos: [0, 0, 1], state: "minecraft:grass_block{snowy:false}"},
        {pos: [0, 0, 2], state: "minecraft:grass_block{snowy:false}"},
        {pos: [0, 0, 3], state: "minecraft:grass_block{snowy:false}"},
        {pos: [0, 0, 4], state: "minecraft:grass_block{snowy:false}"},
        {pos: [0, 0, 5], state: "minecraft:grass_block{snowy:false}"},
        {pos: [0, 0, 6], state: "minecraft:grass_block{snowy:false}"},
        {pos: [1, 0, 0], state: "minecraft:grass_block{snowy:false}"},
        {pos: [1, 0, 1], state: "minecraft:grass_block{snowy:false}"},
        {pos: [1, 0, 2], state: "minecraft:grass_block{snowy:false}"},
        {pos: [1, 0, 3], state: "minecraft:grass_block{snowy:false}"},
        {pos: [1, 0, 4], state: "minecraft:grass_block{snowy:false}"},
        {pos: [1, 0, 5], state: "minecraft:grass_block{snowy:false}"},
        {pos: [1, 0, 6], state: "minecraft:grass_block{snowy:false}"},
        {pos: [2, 0, 0], state: "minecraft:grass_block{snowy:false}"},
        {pos: [2, 0, 1], state: "minecraft:grass_block{snowy:false}"},
        {pos: [2, 0, 2], state: "minecraft:grass_block{snowy:false}"},
        {pos: [2, 0, 3], state: "minecraft:grass_block{snowy:false}"},
        {pos: [2, 0, 4], state: "minecraft:grass_block{snowy:false}"},
        {pos: [2, 0, 5], state: "minecraft:grass_block{snowy:false}"},
        {pos: [2, 0, 6], state: "minecraft:grass_block{snowy:false}"},
        {pos: [3, 0, 0], state: "minecraft:grass_block{snowy:false}"},
        {pos: [3, 0, 1], state: "minecraft:grass_block{snowy:false}"},
        {pos: [3, 0, 2], state: "minecraft:grass_block{snowy:false}"},
        {pos: [3, 0, 3], state: "minecraft:grass_block{snowy:false}"},
        {pos: [3, 0, 4], state: "minecraft:grass_block{snowy:false}"},
        {pos: [3, 0, 5], state: "minecraft:grass_block{snowy:false}"},
        {pos: [3, 0, 6], state: "minecraft:grass_block{snowy:false}"},
        {pos: [4, 0, 0], state: "minecraft:grass_block{snowy:false}"},
        {pos: [4, 0, 1], state: "minecraft:grass_block{snowy:false}"},
        {pos: [4, 0, 2], state: "minecraft:grass_block{snowy:false}"},
        {pos: [4, 0, 3], state: "minecraft:grass_block{snowy:false}"},
        {pos: [4, 0, 4], state: "crabbersdelight:crab_trap{facing:south,hanging:false,waterlogged:true}", nbt: {handler: {Items: [{Slot: 0, count: 64, id: "minecraft:salmon"}], Size: 28}, id: "crabbersdelight:crab_trap", tickCounter: 912}},
        {pos: [4, 0, 5], state: "minecraft:water{level:0}"},
        {pos: [4, 0, 6], state: "minecraft:grass_block{snowy:false}"},
        {pos: [5, 0, 0], state: "minecraft:grass_block{snowy:false}"},
        {pos: [5, 0, 1], state: "minecraft:grass_block{snowy:false}"},
        {pos: [5, 0, 2], state: "minecraft:grass_block{snowy:false}"},
        {pos: [5, 0, 3], state: "minecraft:grass_block{snowy:false}"},
        {pos: [5, 0, 4], state: "minecraft:dirt"},
        {pos: [5, 0, 5], state: "minecraft:grass_block{snowy:false}"},
        {pos: [5, 0, 6], state: "minecraft:grass_block{snowy:false}"},
        {pos: [6, 0, 0], state: "create:copper_casing"},
        {pos: [6, 0, 1], state: "create:copper_casing"},
        {pos: [6, 0, 2], state: "supplementaries:checker_block"},
        {pos: [6, 0, 3], state: "supplementaries:checker_block"},
        {pos: [6, 0, 4], state: "supplementaries:checker_block"},
        {pos: [6, 0, 5], state: "supplementaries:checker_block"},
        {pos: [6, 0, 6], state: "supplementaries:checker_block"},
        {pos: [7, 0, 0], state: "minecraft:calcite"},
        {pos: [7, 0, 1], state: "minecraft:bricks"},
        {pos: [7, 0, 2], state: "supplementaries:checker_block"},
        {pos: [7, 0, 3], state: "supplementaries:checker_block"},
        {pos: [7, 0, 4], state: "supplementaries:checker_block"},
        {pos: [7, 0, 5], state: "supplementaries:checker_block"},
        {pos: [7, 0, 6], state: "supplementaries:checker_block"},
        {pos: [8, 0, 0], state: "minecraft:calcite"},
        {pos: [8, 0, 1], state: "minecraft:bricks"},
        {pos: [8, 0, 2], state: "supplementaries:checker_block"},
        {pos: [8, 0, 3], state: "supplementaries:checker_block"},
        {pos: [8, 0, 4], state: "supplementaries:checker_block"},
        {pos: [8, 0, 5], state: "supplementaries:checker_block"},
        {pos: [8, 0, 6], state: "supplementaries:checker_block"},
        {pos: [9, 0, 0], state: "minecraft:bricks"},
        {pos: [9, 0, 1], state: "minecraft:bricks"},
        {pos: [9, 0, 2], state: "minecraft:magma_block"},
        {pos: [9, 0, 3], state: "minecraft:bricks"},
        {pos: [9, 0, 4], state: "minecraft:bricks"},
        {pos: [9, 0, 5], state: "minecraft:bricks"},
        {pos: [9, 0, 6], state: "minecraft:bricks"},
        {pos: [10, 0, 0], state: "minecraft:bricks"},
        {pos: [10, 0, 1], state: "minecraft:bricks"},
        {pos: [10, 0, 2], state: "minecraft:bricks"},
        {pos: [10, 0, 3], state: "minecraft:bricks"},
        {pos: [10, 0, 4], state: "minecraft:bricks"},
        {pos: [10, 0, 5], state: "minecraft:bricks"},
        {pos: [10, 0, 6], state: "minecraft:bricks"},
        {pos: [0, 1, 3], state: "supplementaries:lunch_basket{facing:west,hanging:false,open:false,waterlogged:false}", nbt: {id: "supplementaries:lunch_basket"}},
        {pos: [0, 1, 4], state: "brewinandchewin:coaster{invisible:false,rotation:13,size:4}", nbt: {Items: [{Slot: 0b, count: 1, id: "minecraft:apple"}, {Slot: 1b, count: 1, id: "farmersdelight:fish_stew"}, {Slot: 2b, count: 1, id: "minecraft:honey_bottle"}, {Slot: 3b, count: 1, id: "farmersdelight:fried_egg"}], id: "brewinandchewin:coaster"}},
        {pos: [1, 1, 1], state: "handcrafted:oak_table{color:none,shape:east_side,waterlogged:false}"},
        {pos: [1, 1, 2], state: "handcrafted:oak_dining_bench{facing:north,shape:right,waterlogged:false}"},
        {pos: [1, 1, 3], state: "create:red_table_cloth{entity:false}"},
        {pos: [1, 1, 4], state: "create:red_table_cloth{entity:false}"},
        {pos: [2, 1, 1], state: "handcrafted:oak_table{color:none,shape:north_south_center,waterlogged:false}"},
        {pos: [2, 1, 2], state: "handcrafted:oak_dining_bench{facing:north,shape:left,waterlogged:false}"},
        {pos: [2, 1, 3], state: "create:red_table_cloth{entity:false}"},
        {pos: [2, 1, 4], state: "create:red_table_cloth{entity:false}"},
        {pos: [3, 1, 1], state: "handcrafted:oak_table{color:none,shape:west_side,waterlogged:false}"},
        {pos: [3, 1, 3], state: "supplementaries:goblet{light_level:0,waterlogged:false}", nbt: {fluid: {count: 0, id: "moonlight:empty"}, id: "supplementaries:goblet"}},
        {pos: [3, 1, 4], state: "displaydelight:squid_ink_pasta{facing:west}"},
        {pos: [4, 1, 1], state: "barbequesdelight:grill{facing:south,has_campfire:true}", nbt: {auto-serial: {entries: [{burnt: 1b, duration: 280, flipped: 0b, stack: {count: 1, id: "barbequesdelight:burnt_skewer"}, time: 21330}, {burnt: 1b, duration: 280, flipped: 0b, stack: {count: 1, id: "barbequesdelight:burnt_skewer"}, time: 21299}]}, id: "barbequesdelight:grill"}},
        {pos: [5, 1, 1], state: "expandeddelight:juicer{facing:south,waterlogged:false}", nbt: {Container: {}, Inventory: {Items: [], Size: 9}, JuiceTime: 0, JuiceTimeTotal: 0, RecipesUsed: {}, id: "expandeddelight:juicer"}},
        {pos: [5, 1, 4], state: "crabbersdelight:crab_barrel"},
        {pos: [5, 1, 5], state: "crabbersdelight:crab_trap{facing:west,hanging:false,waterlogged:false}", nbt: {handler: {Items: [], Size: 28}, id: "crabbersdelight:crab_trap", tickCounter: 591}},
        {pos: [6, 1, 0], state: "create:fluid_tank{bottom:true,shape:plain,top:false}", nbt: {Boiler: {ActiveHeat: 0, Engines: 0, PassiveHeat: 0b, Supply: 0.0f, Update: 1b, Whistles: 0}, Height: 3, LastKnownPos: [I; 566, 83, 1538], Luminosity: 0, Owner: [I; 304802599, 1694516388, -1556388727, -1859455123], Size: 1, TankContent: {Fluid: {amount: 13250, id: "minecraft:water"}}, Window: 0b, id: "create:fluid_tank"}},
        {pos: [6, 1, 1], state: "create:basin{facing:down}", nbt: {DisabledSpoutput: [], Filter: {}, FilterAmount: 64, FluidOverflow: [], InputItems: {Items: [], Size: 9}, InputTanks: [{Level: {Speed: 0.25f, Target: 1.0f, Value: 1.0f}, TankContent: {Fluid: {amount: 1000, id: "minecraft:water"}}}, {Level: {Speed: 0.25f, Target: 0.0f, Value: 0.0f}, TankContent: {}}], OutputItems: {Items: [], Size: 9}, OutputTanks: [{Level: {Speed: 0.25f, Target: 0.0f, Value: 0.0f}, TankContent: {}}, {Level: {Speed: 0.25f, Target: 0.0f, Value: 0.0f}, TankContent: {}}], Overflow: [], UpTo: 1b, id: "create:basin"}},
        {pos: [7, 1, 0], state: "minecraft:calcite"},
        {pos: [7, 1, 1], state: "handcrafted:oak_counter{counter:calcite,facing:south,type:1}", nbt: {Items: [], id: "handcrafted:container"}},
        {pos: [8, 1, 0], state: "minecraft:calcite"},
        {pos: [8, 1, 1], state: "handcrafted:oak_counter{counter:calcite,facing:south,type:1}", nbt: {Items: [], id: "handcrafted:container"}},
        {pos: [9, 1, 0], state: "minecraft:bricks"},
        {pos: [9, 1, 1], state: "minecraft:calcite"},
        {pos: [9, 1, 2], state: "create:basin{facing:down}", nbt: {DisabledSpoutput: [], Filter: {}, FilterAmount: 64, FluidOverflow: [], InputItems: {Items: [], Size: 9}, InputTanks: [{Level: {Speed: 0.25f, Target: 0.0f, Value: 0.0f}, TankContent: {}}, {Level: {Speed: 0.25f, Target: 0.0f, Value: 0.0f}, TankContent: {}}], OutputItems: {Items: [], Size: 9}, OutputTanks: [{Level: {Speed: 0.25f, Target: 0.0f, Value: 0.0f}, TankContent: {}}, {Level: {Speed: 0.25f, Target: 0.0f, Value: 0.0f}, TankContent: {}}], Overflow: [], UpTo: 1b, id: "create:basin"}},
        {pos: [9, 1, 3], state: "minecraft:campfire{facing:east,lit:true,signal_fire:false,waterlogged:false}", nbt: {CookingTimes: [I; 0, 0, 0, 0], CookingTotalTimes: [I; 0, 0, 0, 0], Items: [], id: "minecraft:campfire"}},
        {pos: [9, 1, 4], state: "farmersdelight:stove{facing:west,lit:true}", nbt: {CookingTimes: [I; 0, 0, 0, 0, 0, 0], CookingTotalTimes: [I; 0, 0, 0, 0, 0, 0], Inventory: {Items: [], Size: 6}, id: "farmersdelight:stove"}},
        {pos: [9, 1, 5], state: "brewinandchewin:keg{facing:west,vertical:false,waterlogged:false}", nbt: {FermentTime: 0, FermentTimeTotal: 9600, FluidTank: {Fluid: {amount: 1000, id: "brewinandchewin:flaxen_cheese"}}, Inventory: {Items: [{Slot: 0, count: 63, id: "minecraft:pumpkin_seeds"}, {Slot: 1, count: 63, id: "minecraft:sugar"}, {Slot: 2, count: 63, id: "minecraft:brown_mushroom"}], Size: 6}, RecipesUsed: {}, components: {"minecraft:custom_data": {Inventory: {Items: [], Size: 6}}}, id: "brewinandchewin:keg"}},
        {pos: [9, 1, 6], state: "brewinandchewin:keg{facing:west,vertical:false,waterlogged:false}", nbt: {FermentTime: 0, FermentTimeTotal: 9600, FluidTank: {}, Inventory: {Items: [{Slot: 0, count: 63, id: "minecraft:wheat_seeds"}, {Slot: 1, count: 63, id: "minecraft:wheat"}, {Slot: 2, count: 63, id: "minecraft:brown_mushroom"}, {Slot: 4, count: 59, id: "brewinandchewin:tankard"}, {Slot: 5, count: 4, id: "brewinandchewin:beer"}], Size: 6}, RecipesUsed: {}, components: {"minecraft:custom_data": {Inventory: {Items: [], Size: 6}}}, id: "brewinandchewin:keg"}},
        {pos: [10, 1, 0], state: "minecraft:bricks"},
        {pos: [10, 1, 1], state: "minecraft:bricks"},
        {pos: [10, 1, 2], state: "create:creative_motor{facing:up}", nbt: {Network: {AddedCapacity: 16384.0f, Capacity: 1572864.0f, Id: 156680413266003L, Size: 4, Stress: 384.0f}, ScrollValue: 96, Speed: 96.0f, id: "create:motor"}},
        {pos: [10, 1, 3], state: "minecraft:bricks"},
        {pos: [10, 1, 4], state: "minecraft:bricks"},
        {pos: [10, 1, 5], state: "minecraft:bricks"},
        {pos: [10, 1, 6], state: "minecraft:bricks"},
        {pos: [1, 2, 1], state: "mynethersdelight:stuffed_hoglin{facing:east,part:head,servings:11}"},
        {pos: [2, 2, 1], state: "mynethersdelight:stuffed_hoglin{facing:east,part:foot,servings:11}"},
        {pos: [3, 2, 1], state: "barbequesdelight:basin{facing:south}", nbt: {auto-serial: {items: [{count: 64, id: "farmersdelight:bacon"}, {count: 64, id: "minecraft:potato"}]}, id: "barbequesdelight:basin"}},
        {pos: [6, 2, 0], state: "create:fluid_tank{bottom:false,shape:plain,top:false}", nbt: {Boiler: {ActiveHeat: 0, Engines: 0, PassiveHeat: 0b, Supply: 0.0f, Update: 0b, Whistles: 0}, Controller: [I; 566, 83, 1538], LastKnownPos: [I; 566, 84, 1538], Luminosity: 0, Owner: [I; 304802599, 1694516388, -1556388727, -1859455123], id: "create:fluid_tank"}},
        {pos: [6, 2, 1], state: "supplementaries:faucet{connected:false,enabled:false,facing:south,has_water:true,light_level:0,powered:false,waterlogged:false}", nbt: {TransferCooldown: 0, fluid: {count: 4, id: "moonlight:water"}, id: "supplementaries:faucet"}},
        {pos: [7, 2, 0], state: "create:weathered_iron_window_pane{east:true,north:false,south:false,waterlogged:false,west:true}"},
        {pos: [7, 2, 1], state: "barbequesdelight:tray{facing:south,support:false}", nbt: {auto-serial: {items: [{count: 64, id: "farmersdelight:minced_beef"}, {count: 64, id: "farmersdelight:pumpkin_slice"}, {count: 64, id: "farmersdelight:cabbage_leaf"}]}, id: "barbequesdelight:tray"}},
        {pos: [8, 2, 0], state: "create:weathered_iron_window_pane{east:true,north:false,south:false,waterlogged:false,west:true}"},
        {pos: [8, 2, 1], state: "farmersdelight:cutting_board{facing:south,waterlogged:false}", nbt: {Inventory: {Items: [{Slot: 0, count: 1, id: "farmersdelight:iron_knife"}], Size: 1}, IsItemCarved: 1b, id: "farmersdelight:cutting_board"}},
        {pos: [9, 2, 0], state: "minecraft:bricks"},
        {pos: [9, 2, 1], state: "supplementaries:jar{facing:west,light_level:0,waterlogged:false}", nbt: {Items: [{Slot: 0b, count: 1, id: "rusticdelight:coffee_cookie"}, {Slot: 1b, count: 1, id: "rusticdelight:coffee_cookie"}, {Slot: 2b, count: 1, id: "expandeddelight:sugar_cookie"}, {Slot: 3b, count: 1, id: "expandeddelight:sugar_cookie"}, {Slot: 4b, count: 1, id: "expandeddelight:chocolate_cookie"}, {Slot: 5b, count: 1, id: "minecraft:cookie"}, {Slot: 6b, count: 1, id: "farmersdelight:sweet_berry_cookie"}, {Slot: 7b, count: 1, id: "farmersdelight:honey_cookie"}, {Slot: 8b, count: 1, id: "rusticdelight:syrup_cookie"}, {Slot: 9b, count: 1, id: "rusticdelight:cherry_blossom_cookie"}, {Slot: 10b, count: 1, id: "rusticdelight:syrup_cookie"}, {Slot: 11b, count: 1, id: "farmersdelight:honey_cookie"}], fluid: {count: 0, id: "moonlight:empty"}, id: "supplementaries:jar"}},
        {pos: [9, 2, 3], state: "farmersdelight:skillet{facing:east,support:true,waterlogged:false}", nbt: {CookTime: 0, CookTimeTotal: 120, Inventory: {Items: [], Size: 1}, Skillet: {count: 1, id: "farmersdelight:skillet"}, id: "farmersdelight:skillet"}},
        {pos: [9, 2, 4], state: "farmersdelight:cooking_pot{facing:west,support:none,waterlogged:false}", nbt: {Container: {}, CookTime: 0, CookTimeTotal: 0, Inventory: {Items: [], Size: 9}, RecipesUsed: {}, id: "farmersdelight:cooking_pot"}},
        {pos: [9, 2, 5], state: "brewinandchewin:unripe_flaxen_cheese_wheel{age:1}"},
        {pos: [9, 2, 6], state: "brewinandchewin:coaster{invisible:false,rotation:3,size:1}", nbt: {Items: [{Slot: 0b, count: 1, id: "brewinandchewin:beer"}], id: "brewinandchewin:coaster"}},
        {pos: [10, 2, 0], state: "minecraft:bricks"},
        {pos: [10, 2, 1], state: "minecraft:bricks"},
        {pos: [10, 2, 2], state: "createcasing:copper_encased_shaft{axis:y}", nbt: {Network: {Capacity: 1572864.0f, Id: 156680413266003L, Size: 4, Stress: 384.0f}, Source: [I; 570, 83, 1540], Speed: 96.0f, id: "createcasing:casing_encased_shaft"}},
        {pos: [10, 2, 3], state: "minecraft:bricks"},
        {pos: [10, 2, 4], state: "minecraft:bricks"},
        {pos: [10, 2, 5], state: "brewinandchewin:ice_crate"},
        {pos: [10, 2, 6], state: "brewinandchewin:ice_crate"},
        {pos: [6, 3, 0], state: "create:fluid_tank{bottom:false,shape:plain,top:true}", nbt: {Boiler: {ActiveHeat: 0, Engines: 0, PassiveHeat: 0b, Supply: 0.0f, Update: 0b, Whistles: 0}, Controller: [I; 566, 83, 1538], LastKnownPos: [I; 566, 85, 1538], Luminosity: 0, Owner: [I; 304802599, 1694516388, -1556388727, -1859455123], id: "create:fluid_tank"}},
        {pos: [7, 3, 0], state: "create:weathered_iron_window_pane{east:true,north:false,south:false,waterlogged:false,west:true}"},
        {pos: [8, 3, 0], state: "create:weathered_iron_window_pane{east:true,north:false,south:false,waterlogged:false,west:true}"},
        {pos: [9, 3, 0], state: "minecraft:bricks"},
        {pos: [9, 3, 2], state: "createcasing:copper_mixer", nbt: {NeedsUpdate: 0b, Network: {AddedStress: 4.0f, Capacity: 1572864.0f, Id: 156680413266003L, Size: 4, Stress: 384.0f}, Owner: [I; 304802599, 1694516388, -1556388727, -1859455123], Running: 0b, Source: [I; 570, 85, 1540], Speed: -96.0f, Ticks: 0, id: "createcasing:custom_mixer"}},
        {pos: [9, 3, 3], state: "handcrafted:kitchen_hood{facing:west,waterlogged:false}"},
        {pos: [9, 3, 4], state: "handcrafted:kitchen_hood{facing:west,waterlogged:false}"},
        {pos: [10, 3, 0], state: "minecraft:bricks"},
        {pos: [10, 3, 1], state: "minecraft:bricks"},
        {pos: [10, 3, 2], state: "createcasing:copper_encased_cogwheel{axis:y,bottom_shaft:true,top_shaft:false}", nbt: {Network: {Capacity: 1572864.0f, Id: 156680413266003L, Size: 4, Stress: 384.0f}, Source: [I; 570, 84, 1540], Speed: 96.0f, id: "createcasing:casing_encased_cogwheel"}},
        {pos: [10, 3, 3], state: "minecraft:bricks"},
        {pos: [10, 3, 4], state: "minecraft:bricks"},
        {pos: [6, 4, 0], state: "create:copper_casing"},
        {pos: [7, 4, 0], state: "create:copper_casing"},
        {pos: [8, 4, 0], state: "create:copper_casing"},
        {pos: [9, 4, 0], state: "create:copper_casing"},
        {pos: [9, 4, 1], state: "create:copper_casing"},
        {pos: [9, 4, 2], state: "create:copper_casing"},
        {pos: [9, 4, 3], state: "create:copper_casing"},
        {pos: [9, 4, 4], state: "create:copper_casing"},
        {pos: [10, 4, 0], state: "create:copper_casing"},
        {pos: [10, 4, 1], state: "create:copper_casing"},
        {pos: [10, 4, 2], state: "create:copper_casing"},
        {pos: [10, 4, 3], state: "create:copper_casing"},
        {pos: [10, 4, 4], state: "create:copper_casing"}
    ],
    entities: [],
    palette: [
        "minecraft:grass_block{snowy:false}",
        "minecraft:dirt",
        "create:copper_casing",
        "supplementaries:checker_block",
        "minecraft:calcite",
        "minecraft:bricks",
        "minecraft:magma_block",
        "crabbersdelight:crab_barrel",
        "brewinandchewin:ice_crate",
        "minecraft:water{level:0}",
        "handcrafted:oak_table{color:none,shape:east_side,waterlogged:false}",
        "handcrafted:oak_dining_bench{facing:north,shape:right,waterlogged:false}",
        "create:red_table_cloth{entity:false}",
        "handcrafted:oak_table{color:none,shape:north_south_center,waterlogged:false}",
        "handcrafted:oak_dining_bench{facing:north,shape:left,waterlogged:false}",
        "handcrafted:oak_table{color:none,shape:west_side,waterlogged:false}",
        "displaydelight:squid_ink_pasta{facing:west}",
        "mynethersdelight:stuffed_hoglin{facing:east,part:head,servings:11}",
        "mynethersdelight:stuffed_hoglin{facing:east,part:foot,servings:11}",
        "create:weathered_iron_window_pane{east:true,north:false,south:false,waterlogged:false,west:true}",
        "brewinandchewin:unripe_flaxen_cheese_wheel{age:1}",
        "handcrafted:kitchen_hood{facing:west,waterlogged:false}",
        "crabbersdelight:crab_trap{facing:south,hanging:false,waterlogged:true}",
        "supplementaries:lunch_basket{facing:west,hanging:false,open:false,waterlogged:false}",
        "brewinandchewin:coaster{invisible:false,rotation:13,size:4}",
        "supplementaries:goblet{light_level:0,waterlogged:false}",
        "barbequesdelight:grill{facing:south,has_campfire:true}",
        "expandeddelight:juicer{facing:south,waterlogged:false}",
        "crabbersdelight:crab_trap{facing:west,hanging:false,waterlogged:false}",
        "create:fluid_tank{bottom:true,shape:plain,top:false}",
        "create:basin{facing:down}",
        "handcrafted:oak_counter{counter:calcite,facing:south,type:1}",
        "minecraft:campfire{facing:east,lit:true,signal_fire:false,waterlogged:false}",
        "farmersdelight:stove{facing:west,lit:true}",
        "brewinandchewin:keg{facing:west,vertical:false,waterlogged:false}",
        "create:creative_motor{facing:up}",
        "barbequesdelight:basin{facing:south}",
        "create:fluid_tank{bottom:false,shape:plain,top:false}",
        "supplementaries:faucet{connected:false,enabled:false,facing:south,has_water:true,light_level:0,powered:false,waterlogged:false}",
        "barbequesdelight:tray{facing:south,support:false}",
        "farmersdelight:cutting_board{facing:south,waterlogged:false}",
        "supplementaries:jar{facing:west,light_level:0,waterlogged:false}",
        "farmersdelight:skillet{facing:east,support:true,waterlogged:false}",
        "farmersdelight:cooking_pot{facing:west,support:none,waterlogged:false}",
        "brewinandchewin:coaster{invisible:false,rotation:3,size:1}",
        "createcasing:copper_encased_shaft{axis:y}",
        "create:fluid_tank{bottom:false,shape:plain,top:true}",
        "createcasing:copper_mixer",
        "createcasing:copper_encased_cogwheel{axis:y,bottom_shaft:true,top_shaft:false}"
    ],
    "brewinandchewin:data_version": 100
}